Workbook

Sheet Dashboard
B1: Airline Flight Analytics - Complete Dashboard
B4: 1. FLIGHT PERFORMANCE
B5: TOTAL FLIGHTS | C5: OPERATED FLIGHTS | D5: ON-TIME FLIGHTS | E5: ON-TIME % (of operated) | F5: AVG DURATION (min) | G5: AVG DISTANCE (KM)
B6: ='Flight Performance'!B6 -> 10000 | C6: ='Flight Performance'!C6 -> 9384 | D6: ='Flight Performance'!D6 -> 1808 | E6: ='Flight Performance'!E6 -> 0.19266837 | F6: ='Flight Performance'!F6 -> 191.20759 | G6: ='Flight Performance'!G6 -> 1371.7468
B25: 2. DELAY ANALYSIS
B26: DELAYED FLIGHTS | C26: DELAY RATE (of operated) | D26: AVG DEP DELAY (min) | E26: AVG ARR DELAY (min) | F26: MAX ARR DELAY (min) | G26: DELAYS OVER 30 MIN
B27: ='Delay Analysis'!B6 -> 7576 | C27: ='Delay Analysis'!C6 -> 0.80733163 | D27: ='Delay Analysis'!D6 -> 16.822677 | E27: ='Delay Analysis'!E6 -> 20.262788 | F27: ='Delay Analysis'!F6 -> 130 | G27: ='Delay Analysis'!G6 -> 2777
B46: 3. CANCELLATION ANALYSIS
B47: CANCELLED FLIGHTS | C47: CANCELLATION RATE | D47: TOP REASON | E47: SEATS AFFECTED | F47: AVG CANCELLED / MONTH | G47: HIGHEST CANCEL-RATE AIRLINE
B48: ='Cancellation Analysis'!B6 -> 616 | C48: ='Cancellation Analysis'!C6 -> 0.0616 | D48: ='Cancellation Analysis'!D6 -> Technical Issue | E48: ='Cancellation Analysis'!E6 -> 113268 | F48: ='Cancellation Analysis'!F6 -> 51.333333 | G48: ='Cancellation Analysis'!G6 -> IndiGo
B67: 4. PASSENGER ANALYTICS
B68: TOTAL PASSENGERS | C68: TOTAL SEATS (operated) | D68: OVERALL LOAD FACTOR | E68: AVG PAX PER FLIGHT | F68: AVG TICKET PRICE (₹) | G68: EMPTY SEATS
B69: ='Passenger Analytics'!B6 -> 1346015 | C69: ='Passenger Analytics'!C6 -> 1730361 | D69: ='Passenger Analytics'!D6 -> 0.77788103 | E69: ='Passenger Analytics'!E6 -> 143.43723 | F69: ='Passenger Analytics'!F6 -> 6895.9763 | G69: ='Passenger Analytics'!G6 -> 384346
B88: 5. ROUTE ANALYTICS
B89: TOP ROUTE (by pax) | C89: TOP ROUTE PASSENGERS | D89: AVG DISTANCE (KM) | E89: LONGEST ROUTE (KM) | F89: SHORTEST ROUTE (KM) | G89: TOP-10 SHARE OF PAX
B90: ='Route Analytics'!B6 -> Ahmedabad - Goa | C90: ='Route Analytics'!C6 -> 19700 | D90: ='Route Analytics'!D6 -> 1371.7468 | E90: ='Route Analytics'!E6 -> 2399 | F90: ='Route Analytics'!F6 -> 350 | G90: ='Route Analytics'!G6 -> 0.13082246
B109: 6. AIRPORT PERFORMANCE
B110: AIRPORTS | C110: TOTAL DEPARTURES | D110: BUSIEST AIRPORT | E110: HIGHEST DELAY RATE | F110: HIGHEST CANCEL RATE | G110: BEST ON-TIME AIRPORT
B111: ='Airport Performance'!B6 -> 10 | C111: ='Airport Performance'!C6 -> 10000 | D111: ='Airport Performance'!D6 -> Pune (PNQ) | E111: ='Airport Performance'!E6 -> Kolkata (CCU) | F111: ='Airport Performance'!F6 -> Delhi (DEL) | G111: ='Airport Performance'!G6 -> Pune (PNQ)
B130: 7. AIRLINE PERFORMANCE
B131: AIRLINES | C131: MOST FLIGHTS | D131: TOP REVENUE | E131: TOP PROFIT | F131: BEST ON-TIME (lowest delay rate) | G131: HIGHEST LOAD FACTOR
B132: ='Airline Performance'!B6 -> 6 | C132: ='Airline Performance'!C6 -> IndiGo | D132: ='Airline Performance'!D6 -> IndiGo | E132: ='Airline Performance'!E6 -> IndiGo | F132: ='Airline Performance'!F6 -> Vistara | G132: ='Airline Performance'!G6 -> Air India
B151: 8. REVENUE DASHBOARD
B152: TOTAL REVENUE | C152: TICKET REVENUE | D152: BAGGAGE REVENUE | E152: ANCILLARY REVENUE | F152: OPERATING COST | G152: NET PROFIT | H152: PROFIT MARGIN
B153: ='Revenue Dashboard'!B6 -> 1036.5107 | C153: ='Revenue Dashboard'!C6 -> 928.80041 | D153: ='Revenue Dashboard'!D6 -> 46.964298 | E153: ='Revenue Dashboard'!E6 -> 60.745986 | F153: ='Revenue Dashboard'!F6 -> 756.63315 | G153: ='Revenue Dashboard'!G6 -> 279.87755 | H153: ='Revenue Dashboard'!H6 -> 0.27001897

Sheet Flight Performance
B1: Flight Performance
B5: TOTAL FLIGHTS | C5: OPERATED FLIGHTS | D5: ON-TIME FLIGHTS | E5: ON-TIME % (of operated) | F5: AVG DURATION (min) | G5: AVG DISTANCE (KM)
B6: =COUNTA(Flight_Data!$A$2:$A$10001) -> 10000 | C6: =COUNTIF(Flight_Data!$R$2:$R$10001,"No") -> 9384 | D6: =COUNTIF(Flight_Data!$Q$2:$Q$10001,"On Time") -> 1808 | E6: =IFERROR(D6/C6,0) -> 0.19266837 | F6: =AVERAGEIFS(Flight_Data!$N$2:$N$10001,Flight_Data!$R$2:$R$10001,"No") -> 191.20759 | G6: =AVERAGE(Flight_Data!$I$2:$I$10001) -> 1371.7468
B41: Flight Status Summary | F41: Monthly Flights | K41: Flights by Origin Region
B42: Flight Status | C42: Flights | D42: % of Total | F42: Month | G42: Total Flights | H42: Operated | I42: Cancelled | K42: Region | L42: Flights | M42: Avg Distance (KM)
B43: On Time | C43: =COUNTIF(Flight_Data!$Q$2:$Q$10001,B43) -> 1808 | D43: =IFERROR(C43/COUNTA(Flight_Data!$A$2:$A$10001),0) -> 0.1808 | F43: Jan | G43: =COUNTIF(Flight_Data!$AJ$2:$AJ$10001,F43) -> 851 | H43: =COUNTIFS(Flight_Data!$AJ$2:$AJ$10001,F43,Flight_Data!$R$2:$R$10001,"No") -> 803 | I43: =G43-H43 -> 48 | K43: East | L43: =COUNTIF(Flight_Data!$AE$2:$AE$10001,K43) -> 938 | M43: =AVERAGEIF(Flight_Data!$AE$2:$AE$10001,K43,Flight_Data!$I$2:$I$10001) -> 1363.8902
B44: Delayed <30 min | C44: =COUNTIF(Flight_Data!$Q$2:$Q$10001,B44) -> 4799 | D44: =IFERROR(C44/COUNTA(Flight_Data!$A$2:$A$10001),0) -> 0.4799 | F44: Feb | G44: =COUNTIF(Flight_Data!$AJ$2:$AJ$10001,F44) -> 753 | H44: =COUNTIFS(Flight_Data!$AJ$2:$AJ$10001,F44,Flight_Data!$R$2:$R$10001,"No") -> 708 | I44: =G44-H44 -> 45 | K44: North | L44: =COUNTIF(Flight_Data!$AE$2:$AE$10001,K44) -> 2024 | M44: =AVERAGEIF(Flight_Data!$AE$2:$AE$10001,K44,Flight_Data!$I$2:$I$10001) -> 1388.504
B45: Delayed 30-120 min | C45: =COUNTIF(Flight_Data!$Q$2:$Q$10001,B45) -> 2774 | D45: =IFERROR(C45/COUNTA(Flight_Data!$A$2:$A$10001),0) -> 0.2774 | F45: Mar | G45: =COUNTIF(Flight_Data!$AJ$2:$AJ$10001,F45) -> 838 | H45: =COUNTIFS(Flight_Data!$AJ$2:$AJ$10001,F45,Flight_Data!$R$2:$R$10001,"No") -> 789 | I45: =G45-H45 -> 49 | K45: South | L45: =COUNTIF(Flight_Data!$AE$2:$AE$10001,K45) -> 2955 | M45: =AVERAGEIF(Flight_Data!$AE$2:$AE$10001,K45,Flight_Data!$I$2:$I$10001) -> 1361.957
B46: Delayed >120 min | C46: =COUNTIF(Flight_Data!$Q$2:$Q$10001,B46) -> 3 | D46: =IFERROR(C46/COUNTA(Flight_Data!$A$2:$A$10001),0) -> 0.0003 | F46: Apr | G46: =COUNTIF(Flight_Data!$AJ$2:$AJ$10001,F46) -> 812 | H46: =COUNTIFS(Flight_Data!$AJ$2:$AJ$10001,F46,Flight_Data!$R$2:$R$10001,"No") -> 753 | I46: =G46-H46 -> 59 | K46: West | L46: =COUNTIF(Flight_Data!$AE$2:$AE$10001,K46) -> 4083 | M46: =AVERAGEIF(Flight_Data!$AE$2:$AE$10001,K46,Flight_Data!$I$2:$I$10001) -> 1372.3301
B47: Cancelled | C47: =COUNTIF(Flight_Data!$Q$2:$Q$10001,B47) -> 616 | D47: =IFERROR(C47/COUNTA(Flight_Data!$A$2:$A$10001),0) -> 0.0616 | F47: May | G47: =COUNTIF(Flight_Data!$AJ$2:$AJ$10001,F47) -> 846 | H47: =COUNTIFS(Flight_Data!$AJ$2:$AJ$10001,F47,Flight_Data!$R$2:$R$10001,"No") -> 798 | I47: =G47-H47 -> 48 | K47: Total | L47: =SUM(L43:L46) -> 10000 | M47: =AVERAGE(Flight_Data!$I$2:$I$10001) -> 1371.7468
B48: Total | C48: =SUM(C43:C47) -> 10000 | D48: =SUM(D43:D47) -> 1 | F48: Jun | G48: =COUNTIF(Flight_Data!$AJ$2:$AJ$10001,F48) -> 829 | H48: =COUNTIFS(Flight_Data!$AJ$2:$AJ$10001,F48,Flight_Data!$R$2:$R$10001,"No") -> 775 | I48: =G48-H48 -> 54
F49: Jul | G49: =COUNTIF(Flight_Data!$AJ$2:$AJ$10001,F49) -> 885 | H49: =COUNTIFS(Flight_Data!$AJ$2:$AJ$10001,F49,Flight_Data!$R$2:$R$10001,"No") -> 837 | I49: =G49-H49 -> 48
F50: Aug | G50: =COUNTIF(Flight_Data!$AJ$2:$AJ$10001,F50) -> 822 | H50: =COUNTIFS(Flight_Data!$AJ$2:$AJ$10001,F50,Flight_Data!$R$2:$R$10001,"No") -> 760 | I50: =G50-H50 -> 62
F51: Sep | G51: =COUNTIF(Flight_Data!$AJ$2:$AJ$10001,F51) -> 808 | H51: =COUNTIFS(Flight_Data!$AJ$2:$AJ$10001,F51,Flight_Data!$R$2:$R$10001,"No") -> 766 | I51: =G51-H51 -> 42
B52: Flights by Airline | F52: Oct | G52: =COUNTIF(Flight_Data!$AJ$2:$AJ$10001,F52) -> 831 | H52: =COUNTIFS(Flight_Data!$AJ$2:$AJ$10001,F52,Flight_Data!$R$2:$R$10001,"No") -> 789 | I52: =G52-H52 -> 42
B53: Airline | C53: Flights | D53: Avg Duration (min) | E53: Avg Distance (KM) | F53: Nov | G53: =COUNTIF(Flight_Data!$AJ$2:$AJ$10001,F53) -> 818 | H53: =COUNTIFS(Flight_Data!$AJ$2:$AJ$10001,F53,Flight_Data!$R$2:$R$10001,"No") -> 762 | I53: =G53-H53 -> 56
B54: IndiGo | C54: =COUNTIF(Flight_Data!$C$2:$C$10001,B54) -> 3206 | D54: =AVERAGEIFS(Flight_Data!$N$2:$N$10001,Flight_Data!$C$2:$C$10001,B54,Flight_Data!$R$2:$R$10001,"No") -> 192.13489 | E54: =AVERAGEIF(Flight_Data!$C$2:$C$10001,B54,Flight_Data!$I$2:$I$10001) -> 1378.0989 | F54: Dec | G54: =COUNTIF(Flight_Data!$AJ$2:$AJ$10001,F54) -> 907 | H54: =COUNTIFS(Flight_Data!$AJ$2:$AJ$10001,F54,Flight_Data!$R$2:$R$10001,"No") -> 844 | I54: =G54-H54 -> 63
B55: Air India | C55: =COUNTIF(Flight_Data!$C$2:$C$10001,B55) -> 1812 | D55: =AVERAGEIFS(Flight_Data!$N$2:$N$10001,Flight_Data!$C$2:$C$10001,B55,Flight_Data!$R$2:$R$10001,"No") -> 188.73135 | E55: =AVERAGEIF(Flight_Data!$C$2:$C$10001,B55,Flight_Data!$I$2:$I$10001) -> 1355.9503 | F55: Total | G55: =SUM(G43:G54) -> 10000 | H55: =SUM(H43:H54) -> 9384 | I55: =SUM(I43:I54) -> 616
B56: Vistara | C56: =COUNTIF(Flight_Data!$C$2:$C$10001,B56) -> 1460 | D56: =AVERAGEIFS(Flight_Data!$N$2:$N$10001,Flight_Data!$C$2:$C$10001,B56,Flight_Data!$R$2:$R$10001,"No") -> 190.91142 | E56: =AVERAGEIF(Flight_Data!$C$2:$C$10001,B56,Flight_Data!$I$2:$I$10001) -> 1362.5486
B57: SpiceJet | C57: =COUNTIF(Flight_Data!$C$2:$C$10001,B57) -> 1321 | D57: =AVERAGEIFS(Flight_Data!$N$2:$N$10001,Flight_Data!$C$2:$C$10001,B57,Flight_Data!$R$2:$R$10001,"No") -> 191.13162 | E57: =AVERAGEIF(Flight_Data!$C$2:$C$10001,B57,Flight_Data!$I$2:$I$10001) -> 1366.2695
B58: Akasa Air | C58: =COUNTIF(Flight_Data!$C$2:$C$10001,B58) -> 1222 | D58: =AVERAGEIFS(Flight_Data!$N$2:$N$10001,Flight_Data!$C$2:$C$10001,B58,Flight_Data!$R$2:$R$10001,"No") -> 190.27408 | E58: =AVERAGEIF(Flight_Data!$C$2:$C$10001,B58,Flight_Data!$I$2:$I$10001) -> 1366.3486
B59: Air India Express | C59: =COUNTIF(Flight_Data!$C$2:$C$10001,B59) -> 979 | D59: =AVERAGEIFS(Flight_Data!$N$2:$N$10001,Flight_Data!$C$2:$C$10001,B59,Flight_Data!$R$2:$R$10001,"No") -> 194.51251 | E59: =AVERAGEIF(Flight_Data!$C$2:$C$10001,B59,Flight_Data!$I$2:$I$10001) -> 1408.0286
B60: Total | C60: =SUM(C54:C59) -> 10000 | D60: =AVERAGEIFS(Flight_Data!$N$2:$N$10001,Flight_Data!$R$2:$R$10001,"No") -> 191.20759 | E60: =AVERAGE(Flight_Data!$I$2:$I$10001) -> 1371.7468

Sheet Delay Analysis
B1: Delay Analysis
B5: DELAYED FLIGHTS | C5: DELAY RATE (of operated) | D5: AVG DEP DELAY (min) | E5: AVG ARR DELAY (min) | F5: MAX ARR DELAY (min) | G5: DELAYS OVER 30 MIN
B6: =COUNTIF(Flight_Data!$Q$2:$Q$10001,"Delayed*") -> 7576 | C6: =IFERROR(B6/COUNTIF(Flight_Data!$R$2:$R$10001,"No"),0) -> 0.80733163 | D6: =AVERAGEIFS(Flight_Data!$O$2:$O$10001,Flight_Data!$R$2:$R$10001,"No") -> 16.822677 | E6: =AVERAGEIFS(Flight_Data!$P$2:$P$10001,Flight_Data!$R$2:$R$10001,"No") -> 20.262788 | F6: =MAX(Flight_Data!$P$2:$P$10001) -> 130 | G6: =COUNTIF(Flight_Data!$Q$2:$Q$10001,"Delayed 30-120 min")+COUNTIF(Flight_Data!$Q$2:$Q$10001,"Delayed >120 min") -> 2777
B41: Delay Category | F41: Monthly Delay Trend
B42: Category | C42: Flights | D42: % of Operated | F42: Month | G42: Avg Dep Delay (min) | H42: Avg Arr Delay (min) | I42: Delayed Flights | J42: Delay Rate
B43: On Time | C43: =COUNTIF(Flight_Data!$Q$2:$Q$10001,B43) -> 1808 | D43: =IFERROR(C43/COUNTIF(Flight_Data!$R$2:$R$10001,"No"),0) -> 0.19266837 | F43: Jan | G43: =IFERROR(AVERAGEIFS(Flight_Data!$O$2:$O$10001,Flight_Data!$AJ$2:$AJ$10001,F43,Flight_Data!$R$2:$R$10001,"No"),0) -> 16.645081 | H43: =IFERROR(AVERAGEIFS(Flight_Data!$P$2:$P$10001,Flight_Data!$AJ$2:$AJ$10001,F43,Flight_Data!$R$2:$R$10001,"No"),0) -> 19.478207 | I43: =COUNTIFS(Flight_Data!$AJ$2:$AJ$10001,F43,Flight_Data!$Q$2:$Q$10001,"Delayed*") -> 648 | J43: =IFERROR(I43/COUNTIFS(Flight_Data!$AJ$2:$AJ$10001,F43,Flight_Data!$R$2:$R$10001,"No"),0) -> 0.80697385
B44: Delayed <30 min | C44: =COUNTIF(Flight_Data!$Q$2:$Q$10001,B44) -> 4799 | D44: =IFERROR(C44/COUNTIF(Flight_Data!$R$2:$R$10001,"No"),0) -> 0.51140239 | F44: Feb | G44: =IFERROR(AVERAGEIFS(Flight_Data!$O$2:$O$10001,Flight_Data!$AJ$2:$AJ$10001,F44,Flight_Data!$R$2:$R$10001,"No"),0) -> 17.628531 | H44: =IFERROR(AVERAGEIFS(Flight_Data!$P$2:$P$10001,Flight_Data!$AJ$2:$AJ$10001,F44,Flight_Data!$R$2:$R$10001,"No"),0) -> 21.686441 | I44: =COUNTIFS(Flight_Data!$AJ$2:$AJ$10001,F44,Flight_Data!$Q$2:$Q$10001,"Delayed*") -> 567 | J44: =IFERROR(I44/COUNTIFS(Flight_Data!$AJ$2:$AJ$10001,F44,Flight_Data!$R$2:$R$10001,"No"),0) -> 0.80084746
B45: Delayed 30-120 min | C45: =COUNTIF(Flight_Data!$Q$2:$Q$10001,B45) -> 2774 | D45: =IFERROR(C45/COUNTIF(Flight_Data!$R$2:$R$10001,"No"),0) -> 0.29560955 | F45: Mar | G45: =IFERROR(AVERAGEIFS(Flight_Data!$O$2:$O$10001,Flight_Data!$AJ$2:$AJ$10001,F45,Flight_Data!$R$2:$R$10001,"No"),0) -> 16.726236 | H45: =IFERROR(AVERAGEIFS(Flight_Data!$P$2:$P$10001,Flight_Data!$AJ$2:$AJ$10001,F45,Flight_Data!$R$2:$R$10001,"No"),0) -> 20.485425 | I45: =COUNTIFS(Flight_Data!$AJ$2:$AJ$10001,F45,Flight_Data!$Q$2:$Q$10001,"Delayed*") -> 650 | J45: =IFERROR(I45/COUNTIFS(Flight_Data!$AJ$2:$AJ$10001,F45,Flight_Data!$R$2:$R$10001,"No"),0) -> 0.82382763
B46: Delayed >120 min | C46: =COUNTIF(Flight_Data!$Q$2:$Q$10001,B46) -> 3 | D46: =IFERROR(C46/COUNTIF(Flight_Data!$R$2:$R$10001,"No"),0) -> 0.00031969309 | F46: Apr | G46: =IFERROR(AVERAGEIFS(Flight_Data!$O$2:$O$10001,Flight_Data!$AJ$2:$AJ$10001,F46,Flight_Data!$R$2:$R$10001,"No"),0) -> 16.108898 | H46: =IFERROR(AVERAGEIFS(Flight_Data!$P$2:$P$10001,Flight_Data!$AJ$2:$AJ$10001,F46,Flight_Data!$R$2:$R$10001,"No"),0) -> 20.069057 | I46: =COUNTIFS(Flight_Data!$AJ$2:$AJ$10001,F46,Flight_Data!$Q$2:$Q$10001,"Delayed*") -> 598 | J46: =IFERROR(I46/COUNTIFS(Flight_Data!$AJ$2:$AJ$10001,F46,Flight_Data!$R$2:$R$10001,"No"),0) -> 0.79415671
B47: Total | C47: =SUM(C43:C46) -> 9384 | D47: =SUM(D43:D46) -> 1 | F47: May | G47: =IFERROR(AVERAGEIFS(Flight_Data!$O$2:$O$10001,Flight_Data!$AJ$2:$AJ$10001,F47,Flight_Data!$R$2:$R$10001,"No"),0) -> 17.307018 | H47: =IFERROR(AVERAGEIFS(Flight_Data!$P$2:$P$10001,Flight_Data!$AJ$2:$AJ$10001,F47,Flight_Data!$R$2:$R$10001,"No"),0) -> 20.194236 | I47: =COUNTIFS(Flight_Data!$AJ$2:$AJ$10001,F47,Flight_Data!$Q$2:$Q$10001,"Delayed*") -> 637 | J47: =IFERROR(I47/COUNTIFS(Flight_Data!$AJ$2:$AJ$10001,F47,Flight_Data!$R$2:$R$10001,"No"),0) -> 0.79824561
F48: Jun | G48: =IFERROR(AVERAGEIFS(Flight_Data!$O$2:$O$10001,Flight_Data!$AJ$2:$AJ$10001,F48,Flight_Data!$R$2:$R$10001,"No"),0) -> 17.189677 | H48: =IFERROR(AVERAGEIFS(Flight_Data!$P$2:$P$10001,Flight_Data!$AJ$2:$AJ$10001,F48,Flight_Data!$R$2:$R$10001,"No"),0) -> 19.277419 | I48: =COUNTIFS(Flight_Data!$AJ$2:$AJ$10001,F48,Flight_Data!$Q$2:$Q$10001,"Delayed*") -> 629 | J48: =IFERROR(I48/COUNTIFS(Flight_Data!$AJ$2:$AJ$10001,F48,Flight_Data!$R$2:$R$10001,"No"),0) -> 0.8116129
F49: Jul | G49: =IFERROR(AVERAGEIFS(Flight_Data!$O$2:$O$10001,Flight_Data!$AJ$2:$AJ$10001,F49,Flight_Data!$R$2:$R$10001,"No"),0) -> 16.046595 | H49: =IFERROR(AVERAGEIFS(Flight_Data!$P$2:$P$10001,Flight_Data!$AJ$2:$AJ$10001,F49,Flight_Data!$R$2:$R$10001,"No"),0) -> 20.017921 | I49: =COUNTIFS(Flight_Data!$AJ$2:$AJ$10001,F49,Flight_Data!$Q$2:$Q$10001,"Delayed*") -> 675 | J49: =IFERROR(I49/COUNTIFS(Flight_Data!$AJ$2:$AJ$10001,F49,Flight_Data!$R$2:$R$10001,"No"),0) -> 0.80645161
F50: Aug | G50: =IFERROR(AVERAGEIFS(Flight_Data!$O$2:$O$10001,Flight_Data!$AJ$2:$AJ$10001,F50,Flight_Data!$R$2:$R$10001,"No"),0) -> 17.807895 | H50: =IFERROR(AVERAGEIFS(Flight_Data!$P$2:$P$10001,Flight_Data!$AJ$2:$AJ$10001,F50,Flight_Data!$R$2:$R$10001,"No"),0) -> 21.834211 | I50: =COUNTIFS(Flight_Data!$AJ$2:$AJ$10001,F50,Flight_Data!$Q$2:$Q$10001,"Delayed*") -> 634 | J50: =IFERROR(I50/COUNTIFS(Flight_Data!$AJ$2:$AJ$10001,F50,Flight_Data!$R$2:$R$10001,"No"),0) -> 0.83421053
F51: Sep | G51: =IFERROR(AVERAGEIFS(Flight_Data!$O$2:$O$10001,Flight_Data!$AJ$2:$AJ$10001,F51,Flight_Data!$R$2:$R$10001,"No"),0) -> 17.018277 | H51: =IFERROR(AVERAGEIFS(Flight_Data!$P$2:$P$10001,Flight_Data!$AJ$2:$AJ$10001,F51,Flight_Data!$R$2:$R$10001,"No"),0) -> 21.032637 | I51: =COUNTIFS(Flight_Data!$AJ$2:$AJ$10001,F51,Flight_Data!$Q$2:$Q$10001,"Delayed*") -> 627 | J51: =IFERROR(I51/COUNTIFS(Flight_Data!$AJ$2:$AJ$10001,F51,Flight_Data!$R$2:$R$10001,"No"),0) -> 0.81853786
F52: Oct | G52: =IFERROR(AVERAGEIFS(Flight_Data!$O$2:$O$10001,Flight_Data!$AJ$2:$AJ$10001,F52,Flight_Data!$R$2:$R$10001,"No"),0) -> 16.6109 | H52: =IFERROR(AVERAGEIFS(Flight_Data!$P$2:$P$10001,Flight_Data!$AJ$2:$AJ$10001,F52,Flight_Data!$R$2:$R$10001,"No"),0) -> 19.579214 | I52: =COUNTIFS(Flight_Data!$AJ$2:$AJ$10001,F52,Flight_Data!$Q$2:$Q$10001,"Delayed*") -> 632 | J52: =IFERROR(I52/COUNTIFS(Flight_Data!$AJ$2:$AJ$10001,F52,Flight_Data!$R$2:$R$10001,"No"),0) -> 0.80101394
F53: Nov | G53: =IFERROR(AVERAGEIFS(Flight_Data!$O$2:$O$10001,Flight_Data!$AJ$2:$AJ$10001,F53,Flight_Data!$R$2:$R$10001,"No"),0) -> 16.918635 | H53: =IFERROR(AVERAGEIFS(Flight_Data!$P$2:$P$10001,Flight_Data!$AJ$2:$AJ$10001,F53,Flight_Data!$R$2:$R$10001,"No"),0) -> 20.135171 | I53: =COUNTIFS(Flight_Data!$AJ$2:$AJ$10001,F53,Flight_Data!$Q$2:$Q$10001,"Delayed*") -> 611 | J53: =IFERROR(I53/COUNTIFS(Flight_Data!$AJ$2:$AJ$10001,F53,Flight_Data!$R$2:$R$10001,"No"),0) -> 0.80183727
F54: Dec | G54: =IFERROR(AVERAGEIFS(Flight_Data!$O$2:$O$10001,Flight_Data!$AJ$2:$AJ$10001,F54,Flight_Data!$R$2:$R$10001,"No"),0) -> 16.063981 | H54: =IFERROR(AVERAGEIFS(Flight_Data!$P$2:$P$10001,Flight_Data!$AJ$2:$AJ$10001,F54,Flight_Data!$R$2:$R$10001,"No"),0) -> 19.632701 | I54: =COUNTIFS(Flight_Data!$AJ$2:$AJ$10001,F54,Flight_Data!$Q$2:$Q$10001,"Delayed*") -> 668 | J54: =IFERROR(I54/COUNTIFS(Flight_Data!$AJ$2:$AJ$10001,F54,Flight_Data!$R$2:$R$10001,"No"),0) -> 0.79146919
F55: Total / Avg | G55: =AVERAGEIFS(Flight_Data!$O$2:$O$10001,Flight_Data!$R$2:$R$10001,"No") -> 16.822677 | H55: =AVERAGEIFS(Flight_Data!$P$2:$P$10001,Flight_Data!$R$2:$R$10001,"No") -> 20.262788 | I55: =SUM(I43:I54) -> 7576 | J55: =IFERROR(I55/COUNTIF(Flight_Data!$R$2:$R$10001,"No"),0) -> 0.80733163
B57: Delay by Airline
B58: Airline | C58: Operated | D58: Delayed | E58: Delay Rate | F58: Avg Dep Delay (min) | G58: Avg Arr Delay (min)
B59: IndiGo | C59: =COUNTIFS(Flight_Data!$C$2:$C$10001,B59,Flight_Data!$R$2:$R$10001,"No") -> 2995 | D59: =COUNTIFS(Flight_Data!$C$2:$C$10001,B59,Flight_Data!$Q$2:$Q$10001,"Delayed*") -> 2451 | E59: =IFERROR(D59/C59,0) -> 0.81836394 | F59: =AVERAGEIFS(Flight_Data!$O$2:$O$10001,Flight_Data!$C$2:$C$10001,B59,Flight_Data!$R$2:$R$10001,"No") -> 16.869449 | G59: =AVERAGEIFS(Flight_Data!$P$2:$P$10001,Flight_Data!$C$2:$C$10001,B59,Flight_Data!$R$2:$R$10001,"No") -> 20.483472
B60: Air India | C60: =COUNTIFS(Flight_Data!$C$2:$C$10001,B60,Flight_Data!$R$2:$R$10001,"No") -> 1716 | D60: =COUNTIFS(Flight_Data!$C$2:$C$10001,B60,Flight_Data!$Q$2:$Q$10001,"Delayed*") -> 1374 | E60: =IFERROR(D60/C60,0) -> 0.8006993 | F60: =AVERAGEIFS(Flight_Data!$O$2:$O$10001,Flight_Data!$C$2:$C$10001,B60,Flight_Data!$R$2:$R$10001,"No") -> 16.69289 | G60: =AVERAGEIFS(Flight_Data!$P$2:$P$10001,Flight_Data!$C$2:$C$10001,B60,Flight_Data!$R$2:$R$10001,"No") -> 19.937063
B61: Vistara | C61: =COUNTIFS(Flight_Data!$C$2:$C$10001,B61,Flight_Data!$R$2:$R$10001,"No") -> 1366 | D61: =COUNTIFS(Flight_Data!$C$2:$C$10001,B61,Flight_Data!$Q$2:$Q$10001,"Delayed*") -> 1085 | E61: =IFERROR(D61/C61,0) -> 0.7942899 | F61: =AVERAGEIFS(Flight_Data!$O$2:$O$10001,Flight_Data!$C$2:$C$10001,B61,Flight_Data!$R$2:$R$10001,"No") -> 17.207906 | G61: =AVERAGEIFS(Flight_Data!$P$2:$P$10001,Flight_Data!$C$2:$C$10001,B61,Flight_Data!$R$2:$R$10001,"No") -> 20.464861
B62: SpiceJet | C62: =COUNTIFS(Flight_Data!$C$2:$C$10001,B62,Flight_Data!$R$2:$R$10001,"No") -> 1246 | D62: =COUNTIFS(Flight_Data!$C$2:$C$10001,B62,Flight_Data!$Q$2:$Q$10001,"Delayed*") -> 990 | E62: =IFERROR(D62/C62,0) -> 0.79454254 | F62: =AVERAGEIFS(Flight_Data!$O$2:$O$10001,Flight_Data!$C$2:$C$10001,B62,Flight_Data!$R$2:$R$10001,"No") -> 16.626806 | G62: =AVERAGEIFS(Flight_Data!$P$2:$P$10001,Flight_Data!$C$2:$C$10001,B62,Flight_Data!$R$2:$R$10001,"No") -> 20.055377
B63: Akasa Air | C63: =COUNTIFS(Flight_Data!$C$2:$C$10001,B63,Flight_Data!$R$2:$R$10001,"No") -> 1142 | D63: =COUNTIFS(Flight_Data!$C$2:$C$10001,B63,Flight_Data!$Q$2:$Q$10001,"Delayed*") -> 940 | E63: =IFERROR(D63/C63,0) -> 0.82311734 | F63: =AVERAGEIFS(Flight_Data!$O$2:$O$10001,Flight_Data!$C$2:$C$10001,B63,Flight_Data!$R$2:$R$10001,"No") -> 16.915061 | G63: =AVERAGEIFS(Flight_Data!$P$2:$P$10001,Flight_Data!$C$2:$C$10001,B63,Flight_Data!$R$2:$R$10001,"No") -> 20.221541
B64: Air India Express | C64: =COUNTIFS(Flight_Data!$C$2:$C$10001,B64,Flight_Data!$R$2:$R$10001,"No") -> 919 | D64: =COUNTIFS(Flight_Data!$C$2:$C$10001,B64,Flight_Data!$Q$2:$Q$10001,"Delayed*") -> 736 | E64: =IFERROR(D64/C64,0) -> 0.80087051 | F64: =AVERAGEIFS(Flight_Data!$O$2:$O$10001,Flight_Data!$C$2:$C$10001,B64,Flight_Data!$R$2:$R$10001,"No") -> 16.490751 | G64: =AVERAGEIFS(Flight_Data!$P$2:$P$10001,Flight_Data!$C$2:$C$10001,B64,Flight_Data!$R$2:$R$10001,"No") -> 20.183896
B65: Total | C65: =SUM(C59:C64) -> 9384 | D65: =SUM(D59:D64) -> 7576 | E65: =IFERROR(D65/C65,0) -> 0.80733163 | F65: =AVERAGEIFS(Flight_Data!$O$2:$O$10001,Flight_Data!$R$2:$R$10001,"No") -> 16.822677 | G65: =AVERAGEIFS(Flight_Data!$P$2:$P$10001,Flight_Data!$R$2:$R$10001,"No") -> 20.262788

Sheet Cancellation Analysis
B1: Cancellation Analysis
B5: CANCELLED FLIGHTS | C5: CANCELLATION RATE | D5: TOP REASON | E5: SEATS AFFECTED | F5: AVG CANCELLED / MONTH | G5: HIGHEST CANCEL-RATE AIRLINE
B6: =COUNTIF(Flight_Data!$R$2:$R$10001,"Yes") -> 616 | C6: =IFERROR(B6/COUNTA(Flight_Data!$A$2:$A$10001),0) -> 0.0616 | D6: =INDEX(B43:B47,MATCH(MAX(C43:C47),C43:C47,0)) -> Technical Issue | E6: =SUMIF(Flight_Data!$R$2:$R$10001,"Yes",Flight_Data!$T$2:$T$10001) -> 113268 | F6: =B6/12 -> 51.333333 | G6: =INDEX(J43:J48,MATCH(MAX(M43:M48),M43:M48,0)) -> IndiGo
B41: Cancellation Reasons | F41: Monthly Cancellations | J41: Cancellation by Airline
B42: Reason | C42: Cancelled Flights | D42: % of Cancellations | F42: Month | G42: Cancelled | H42: Cancel Rate | J42: Airline | K42: Total Flights | L42: Cancelled | M42: Cancel Rate
B43: Technical Issue | C43: =COUNTIF(Flight_Data!$S$2:$S$10001,B43) -> 191 | D43: =IFERROR(C43/COUNTIF(Flight_Data!$R$2:$R$10001,"Yes"),0) -> 0.31006494 | F43: Jan | G43: =COUNTIFS(Flight_Data!$AJ$2:$AJ$10001,F43,Flight_Data!$R$2:$R$10001,"Yes") -> 48 | H43: =IFERROR(G43/COUNTIF(Flight_Data!$AJ$2:$AJ$10001,F43),0) -> 0.05640423 | J43: IndiGo | K43: =COUNTIF(Flight_Data!$C$2:$C$10001,J43) -> 3206 | L43: =COUNTIFS(Flight_Data!$C$2:$C$10001,J43,Flight_Data!$R$2:$R$10001,"Yes") -> 211 | M43: =IFERROR(L43/K43,0) -> 0.065814099
B44: Weather | C44: =COUNTIF(Flight_Data!$S$2:$S$10001,B44) -> 159 | D44: =IFERROR(C44/COUNTIF(Flight_Data!$R$2:$R$10001,"Yes"),0) -> 0.25811688 | F44: Feb | G44: =COUNTIFS(Flight_Data!$AJ$2:$AJ$10001,F44,Flight_Data!$R$2:$R$10001,"Yes") -> 45 | H44: =IFERROR(G44/COUNTIF(Flight_Data!$AJ$2:$AJ$10001,F44),0) -> 0.059760956 | J44: Air India | K44: =COUNTIF(Flight_Data!$C$2:$C$10001,J44) -> 1812 | L44: =COUNTIFS(Flight_Data!$C$2:$C$10001,J44,Flight_Data!$R$2:$R$10001,"Yes") -> 96 | M44: =IFERROR(L44/K44,0) -> 0.052980132
B45: Operational Issue | C45: =COUNTIF(Flight_Data!$S$2:$S$10001,B45) -> 122 | D45: =IFERROR(C45/COUNTIF(Flight_Data!$R$2:$R$10001,"Yes"),0) -> 0.19805195 | F45: Mar | G45: =COUNTIFS(Flight_Data!$AJ$2:$AJ$10001,F45,Flight_Data!$R$2:$R$10001,"Yes") -> 49 | H45: =IFERROR(G45/COUNTIF(Flight_Data!$AJ$2:$AJ$10001,F45),0) -> 0.058472554 | J45: Vistara | K45: =COUNTIF(Flight_Data!$C$2:$C$10001,J45) -> 1460 | L45: =COUNTIFS(Flight_Data!$C$2:$C$10001,J45,Flight_Data!$R$2:$R$10001,"Yes") -> 94 | M45: =IFERROR(L45/K45,0) -> 0.064383562
B46: Crew Shortage | C46: =COUNTIF(Flight_Data!$S$2:$S$10001,B46) -> 84 | D46: =IFERROR(C46/COUNTIF(Flight_Data!$R$2:$R$10001,"Yes"),0) -> 0.13636364 | F46: Apr | G46: =COUNTIFS(Flight_Data!$AJ$2:$AJ$10001,F46,Flight_Data!$R$2:$R$10001,"Yes") -> 59 | H46: =IFERROR(G46/COUNTIF(Flight_Data!$AJ$2:$AJ$10001,F46),0) -> 0.072660099 | J46: SpiceJet | K46: =COUNTIF(Flight_Data!$C$2:$C$10001,J46) -> 1321 | L46: =COUNTIFS(Flight_Data!$C$2:$C$10001,J46,Flight_Data!$R$2:$R$10001,"Yes") -> 75 | M46: =IFERROR(L46/K46,0) -> 0.05677517
B47: Airport Closure | C47: =COUNTIF(Flight_Data!$S$2:$S$10001,B47) -> 60 | D47: =IFERROR(C47/COUNTIF(Flight_Data!$R$2:$R$10001,"Yes"),0) -> 0.097402597 | F47: May | G47: =COUNTIFS(Flight_Data!$AJ$2:$AJ$10001,F47,Flight_Data!$R$2:$R$10001,"Yes") -> 48 | H47: =IFERROR(G47/COUNTIF(Flight_Data!$AJ$2:$AJ$10001,F47),0) -> 0.056737589 | J47: Akasa Air | K47: =COUNTIF(Flight_Data!$C$2:$C$10001,J47) -> 1222 | L47: =COUNTIFS(Flight_Data!$C$2:$C$10001,J47,Flight_Data!$R$2:$R$10001,"Yes") -> 80 | M47: =IFERROR(L47/K47,0) -> 0.065466448
B48: Total | C48: =SUM(C43:C47) -> 616 | D48: =SUM(D43:D47) -> 1 | F48: Jun | G48: =COUNTIFS(Flight_Data!$AJ$2:$AJ$10001,F48,Flight_Data!$R$2:$R$10001,"Yes") -> 54 | H48: =IFERROR(G48/COUNTIF(Flight_Data!$AJ$2:$AJ$10001,F48),0) -> 0.065138721 | J48: Air India Express | K48: =COUNTIF(Flight_Data!$C$2:$C$10001,J48) -> 979 | L48: =COUNTIFS(Flight_Data!$C$2:$C$10001,J48,Flight_Data!$R$2:$R$10001,"Yes") -> 60 | M48: =IFERROR(L48/K48,0) -> 0.061287028
F49: Jul | G49: =COUNTIFS(Flight_Data!$AJ$2:$AJ$10001,F49,Flight_Data!$R$2:$R$10001,"Yes") -> 48 | H49: =IFERROR(G49/COUNTIF(Flight_Data!$AJ$2:$AJ$10001,F49),0) -> 0.054237288 | J49: Total | K49: =SUM(K43:K48) -> 10000 | L49: =SUM(L43:L48) -> 616 | M49: =IFERROR(L49/K49,0) -> 0.0616
F50: Aug | G50: =COUNTIFS(Flight_Data!$AJ$2:$AJ$10001,F50,Flight_Data!$R$2:$R$10001,"Yes") -> 62 | H50: =IFERROR(G50/COUNTIF(Flight_Data!$AJ$2:$AJ$10001,F50),0) -> 0.075425791
F51: Sep | G51: =COUNTIFS(Flight_Data!$AJ$2:$AJ$10001,F51,Flight_Data!$R$2:$R$10001,"Yes") -> 42 | H51: =IFERROR(G51/COUNTIF(Flight_Data!$AJ$2:$AJ$10001,F51),0) -> 0.051980198
B52: Cancellation by Origin Region | F52: Oct | G52: =COUNTIFS(Flight_Data!$AJ$2:$AJ$10001,F52,Flight_Data!$R$2:$R$10001,"Yes") -> 42 | H52: =IFERROR(G52/COUNTIF(Flight_Data!$AJ$2:$AJ$10001,F52),0) -> 0.050541516
B53: Region | C53: Total Flights | D53: Cancelled | E53: Cancel Rate | F53: Nov | G53: =COUNTIFS(Flight_Data!$AJ$2:$AJ$10001,F53,Flight_Data!$R$2:$R$10001,"Yes") -> 56 | H53: =IFERROR(G53/COUNTIF(Flight_Data!$AJ$2:$AJ$10001,F53),0) -> 0.068459658
B54: East | C54: =COUNTIF(Flight_Data!$AE$2:$AE$10001,B54) -> 938 | D54: =COUNTIFS(Flight_Data!$AE$2:$AE$10001,B54,Flight_Data!$R$2:$R$10001,"Yes") -> 56 | E54: =IFERROR(D54/C54,0) -> 0.059701493 | F54: Dec | G54: =COUNTIFS(Flight_Data!$AJ$2:$AJ$10001,F54,Flight_Data!$R$2:$R$10001,"Yes") -> 63 | H54: =IFERROR(G54/COUNTIF(Flight_Data!$AJ$2:$AJ$10001,F54),0) -> 0.069459757
B55: North | C55: =COUNTIF(Flight_Data!$AE$2:$AE$10001,B55) -> 2024 | D55: =COUNTIFS(Flight_Data!$AE$2:$AE$10001,B55,Flight_Data!$R$2:$R$10001,"Yes") -> 126 | E55: =IFERROR(D55/C55,0) -> 0.062252964 | F55: Total | G55: =SUM(G43:G54) -> 616 | H55: =IFERROR(G55/COUNTA(Flight_Data!$A$2:$A$10001),0) -> 0.0616
B56: South | C56: =COUNTIF(Flight_Data!$AE$2:$AE$10001,B56) -> 2955 | D56: =COUNTIFS(Flight_Data!$AE$2:$AE$10001,B56,Flight_Data!$R$2:$R$10001,"Yes") -> 187 | E56: =IFERROR(D56/C56,0) -> 0.063282572
B57: West | C57: =COUNTIF(Flight_Data!$AE$2:$AE$10001,B57) -> 4083 | D57: =COUNTIFS(Flight_Data!$AE$2:$AE$10001,B57,Flight_Data!$R$2:$R$10001,"Yes") -> 247 | E57: =IFERROR(D57/C57,0) -> 0.060494734
B58: Total | C58: =SUM(C54:C57) -> 10000 | D58: =SUM(D54:D57) -> 616 | E58: =IFERROR(D58/C58,0) -> 0.0616

Sheet Passenger Analytics
B1: Passenger Analytics
B5: TOTAL PASSENGERS | C5: TOTAL SEATS (operated) | D5: OVERALL LOAD FACTOR | E5: AVG PAX PER FLIGHT | F5: AVG TICKET PRICE (₹) | G5: EMPTY SEATS
B6: =SUM(Flight_Data!$U$2:$U$10001) -> 1346015 | C6: =SUMIF(Flight_Data!$R$2:$R$10001,"No",Flight_Data!$T$2:$T$10001) -> 1730361 | D6: =IFERROR(B6/C6,0) -> 0.77788103 | E6: =AVERAGEIFS(Flight_Data!$U$2:$U$10001,Flight_Data!$R$2:$R$10001,"No") -> 143.43723 | F6: =AVERAGEIFS(Flight_Data!$X$2:$X$10001,Flight_Data!$R$2:$R$10001,"No") -> 6895.9763 | G6: =C6-B6 -> 384346
B41: Cabin Class Summary | H41: Monthly Passengers
B42: Cabin | C42: Flights | D42: Passengers | E42: Seats | F42: Load Factor | H42: Month | I42: Passengers | J42: Seats | K42: Load Factor
B43: Economy | C43: =COUNTIFS(Flight_Data!$W$2:$W$10001,B43,Flight_Data!$R$2:$R$10001,"No") -> 6830 | D43: =SUMIFS(Flight_Data!$U$2:$U$10001,Flight_Data!$W$2:$W$10001,B43,Flight_Data!$R$2:$R$10001,"No") -> 979298 | E43: =SUMIFS(Flight_Data!$T$2:$T$10001,Flight_Data!$W$2:$W$10001,B43,Flight_Data!$R$2:$R$10001,"No") -> 1259170 | F43: =IFERROR(D43/E43,0) -> 0.77773295 | H43: Jan | I43: =SUMIFS(Flight_Data!$U$2:$U$10001,Flight_Data!$AJ$2:$AJ$10001,H43,Flight_Data!$R$2:$R$10001,"No") -> 113586 | J43: =SUMIFS(Flight_Data!$T$2:$T$10001,Flight_Data!$AJ$2:$AJ$10001,H43,Flight_Data!$R$2:$R$10001,"No") -> 147858 | K43: =IFERROR(I43/J43,0) -> 0.76821004
B44: Business | C44: =COUNTIFS(Flight_Data!$W$2:$W$10001,B44,Flight_Data!$R$2:$R$10001,"No") -> 728 | D44: =SUMIFS(Flight_Data!$U$2:$U$10001,Flight_Data!$W$2:$W$10001,B44,Flight_Data!$R$2:$R$10001,"No") -> 104452 | E44: =SUMIFS(Flight_Data!$T$2:$T$10001,Flight_Data!$W$2:$W$10001,B44,Flight_Data!$R$2:$R$10001,"No") -> 134729 | F44: =IFERROR(D44/E44,0) -> 0.77527481 | H44: Feb | I44: =SUMIFS(Flight_Data!$U$2:$U$10001,Flight_Data!$AJ$2:$AJ$10001,H44,Flight_Data!$R$2:$R$10001,"No") -> 101239 | J44: =SUMIFS(Flight_Data!$T$2:$T$10001,Flight_Data!$AJ$2:$AJ$10001,H44,Flight_Data!$R$2:$R$10001,"No") -> 130240 | K44: =IFERROR(I44/J44,0) -> 0.77732647
B45: Mixed | C45: =COUNTIFS(Flight_Data!$W$2:$W$10001,B45,Flight_Data!$R$2:$R$10001,"No") -> 1826 | D45: =SUMIFS(Flight_Data!$U$2:$U$10001,Flight_Data!$W$2:$W$10001,B45,Flight_Data!$R$2:$R$10001,"No") -> 262265 | E45: =SUMIFS(Flight_Data!$T$2:$T$10001,Flight_Data!$W$2:$W$10001,B45,Flight_Data!$R$2:$R$10001,"No") -> 336462 | F45: =IFERROR(D45/E45,0) -> 0.77947881 | H45: Mar | I45: =SUMIFS(Flight_Data!$U$2:$U$10001,Flight_Data!$AJ$2:$AJ$10001,H45,Flight_Data!$R$2:$R$10001,"No") -> 114048 | J45: =SUMIFS(Flight_Data!$T$2:$T$10001,Flight_Data!$AJ$2:$AJ$10001,H45,Flight_Data!$R$2:$R$10001,"No") -> 145678 | K45: =IFERROR(I45/J45,0) -> 0.7828773
B46: Total | C46: =SUM(C43:C45) -> 9384 | D46: =SUM(D43:D45) -> 1346015 | E46: =SUM(E43:E45) -> 1730361 | F46: =IFERROR(D46/E46,0) -> 0.77788103 | H46: Apr | I46: =SUMIFS(Flight_Data!$U$2:$U$10001,Flight_Data!$AJ$2:$AJ$10001,H46,Flight_Data!$R$2:$R$10001,"No") -> 108012 | J46: =SUMIFS(Flight_Data!$T$2:$T$10001,Flight_Data!$AJ$2:$AJ$10001,H46,Flight_Data!$R$2:$R$10001,"No") -> 139652 | K46: =IFERROR(I46/J46,0) -> 0.77343683
H47: May | I47: =SUMIFS(Flight_Data!$U$2:$U$10001,Flight_Data!$AJ$2:$AJ$10001,H47,Flight_Data!$R$2:$R$10001,"No") -> 113712 | J47: =SUMIFS(Flight_Data!$T$2:$T$10001,Flight_Data!$AJ$2:$AJ$10001,H47,Flight_Data!$R$2:$R$10001,"No") -> 146402 | K47: =IFERROR(I47/J47,0) -> 0.7767107
H48: Jun | I48: =SUMIFS(Flight_Data!$U$2:$U$10001,Flight_Data!$AJ$2:$AJ$10001,H48,Flight_Data!$R$2:$R$10001,"No") -> 110336 | J48: =SUMIFS(Flight_Data!$T$2:$T$10001,Flight_Data!$AJ$2:$AJ$10001,H48,Flight_Data!$R$2:$R$10001,"No") -> 142132 | K48: =IFERROR(I48/J48,0) -> 0.77629246
B49: Demand Level | H49: Jul | I49: =SUMIFS(Flight_Data!$U$2:$U$10001,Flight_Data!$AJ$2:$AJ$10001,H49,Flight_Data!$R$2:$R$10001,"No") -> 119672 | J49: =SUMIFS(Flight_Data!$T$2:$T$10001,Flight_Data!$AJ$2:$AJ$10001,H49,Flight_Data!$R$2:$R$10001,"No") -> 153697 | K49: =IFERROR(I49/J49,0) -> 0.77862287
B50: Demand | C50: Flights | D50: Passengers | E50: Seats | F50: Load Factor | H50: Aug | I50: =SUMIFS(Flight_Data!$U$2:$U$10001,Flight_Data!$AJ$2:$AJ$10001,H50,Flight_Data!$R$2:$R$10001,"No") -> 109343 | J50: =SUMIFS(Flight_Data!$T$2:$T$10001,Flight_Data!$AJ$2:$AJ$10001,H50,Flight_Data!$R$2:$R$10001,"No") -> 139986 | K50: =IFERROR(I50/J50,0) -> 0.78109954
B51: Low | C51: =COUNTIFS(Flight_Data!$AI$2:$AI$10001,B51,Flight_Data!$R$2:$R$10001,"No") -> 2826 | D51: =SUMIFS(Flight_Data!$U$2:$U$10001,Flight_Data!$AI$2:$AI$10001,B51,Flight_Data!$R$2:$R$10001,"No") -> 406582 | E51: =SUMIFS(Flight_Data!$T$2:$T$10001,Flight_Data!$AI$2:$AI$10001,B51,Flight_Data!$R$2:$R$10001,"No") -> 521862 | F51: =IFERROR(D51/E51,0) -> 0.77909869 | H51: Sep | I51: =SUMIFS(Flight_Data!$U$2:$U$10001,Flight_Data!$AJ$2:$AJ$10001,H51,Flight_Data!$R$2:$R$10001,"No") -> 110092 | J51: =SUMIFS(Flight_Data!$T$2:$T$10001,Flight_Data!$AJ$2:$AJ$10001,H51,Flight_Data!$R$2:$R$10001,"No") -> 141514 | K51: =IFERROR(I51/J51,0) -> 0.77795836
B52: Medium | C52: =COUNTIFS(Flight_Data!$AI$2:$AI$10001,B52,Flight_Data!$R$2:$R$10001,"No") -> 4679 | D52: =SUMIFS(Flight_Data!$U$2:$U$10001,Flight_Data!$AI$2:$AI$10001,B52,Flight_Data!$R$2:$R$10001,"No") -> 670650 | E52: =SUMIFS(Flight_Data!$T$2:$T$10001,Flight_Data!$AI$2:$AI$10001,B52,Flight_Data!$R$2:$R$10001,"No") -> 863424 | F52: =IFERROR(D52/E52,0) -> 0.7767331 | H52: Oct | I52: =SUMIFS(Flight_Data!$U$2:$U$10001,Flight_Data!$AJ$2:$AJ$10001,H52,Flight_Data!$R$2:$R$10001,"No") -> 114664 | J52: =SUMIFS(Flight_Data!$T$2:$T$10001,Flight_Data!$AJ$2:$AJ$10001,H52,Flight_Data!$R$2:$R$10001,"No") -> 146809 | K52: =IFERROR(I52/J52,0) -> 0.78104203
B53: High | C53: =COUNTIFS(Flight_Data!$AI$2:$AI$10001,B53,Flight_Data!$R$2:$R$10001,"No") -> 1879 | D53: =SUMIFS(Flight_Data!$U$2:$U$10001,Flight_Data!$AI$2:$AI$10001,B53,Flight_Data!$R$2:$R$10001,"No") -> 268783 | E53: =SUMIFS(Flight_Data!$T$2:$T$10001,Flight_Data!$AI$2:$AI$10001,B53,Flight_Data!$R$2:$R$10001,"No") -> 345075 | F53: =IFERROR(D53/E53,0) -> 0.77891183 | H53: Nov | I53: =SUMIFS(Flight_Data!$U$2:$U$10001,Flight_Data!$AJ$2:$AJ$10001,H53,Flight_Data!$R$2:$R$10001,"No") -> 109135 | J53: =SUMIFS(Flight_Data!$T$2:$T$10001,Flight_Data!$AJ$2:$AJ$10001,H53,Flight_Data!$R$2:$R$10001,"No") -> 141270 | K53: =IFERROR(I53/J53,0) -> 0.77252778
B54: Total | C54: =SUM(C51:C53) -> 9384 | D54: =SUM(D51:D53) -> 1346015 | E54: =SUM(E51:E53) -> 1730361 | F54: =IFERROR(D54/E54,0) -> 0.77788103 | H54: Dec | I54: =SUMIFS(Flight_Data!$U$2:$U$10001,Flight_Data!$AJ$2:$AJ$10001,H54,Flight_Data!$R$2:$R$10001,"No") -> 122176 | J54: =SUMIFS(Flight_Data!$T$2:$T$10001,Flight_Data!$AJ$2:$AJ$10001,H54,Flight_Data!$R$2:$R$10001,"No") -> 155123 | K54: =IFERROR(I54/J54,0) -> 0.78760725
H55: Total | I55: =SUM(I43:I54) -> 1346015 | J55: =SUM(J43:J54) -> 1730361 | K55: =IFERROR(I55/J55,0) -> 0.77788103
B57: Booking Channel
B58: Channel | C58: Passengers | D58: % Share
B59: Online | C59: =SUMIFS(Flight_Data!$U$2:$U$10001,Flight_Data!$AH$2:$AH$10001,B59,Flight_Data!$R$2:$R$10001,"No") -> 744458 | D59: =IFERROR(C59/SUM(Flight_Data!$U$2:$U$10001),0) -> 0.55308299
B60: Travel Agent | C60: =SUMIFS(Flight_Data!$U$2:$U$10001,Flight_Data!$AH$2:$AH$10001,B60,Flight_Data!$R$2:$R$10001,"No") -> 246664 | D60: =IFERROR(C60/SUM(Flight_Data!$U$2:$U$10001),0) -> 0.18325502
B61: Corporate | C61: =SUMIFS(Flight_Data!$U$2:$U$10001,Flight_Data!$AH$2:$AH$10001,B61,Flight_Data!$R$2:$R$10001,"No") -> 222962 | D61: =IFERROR(C61/SUM(Flight_Data!$U$2:$U$10001),0) -> 0.165646
B62: Airport Counter | C62: =SUMIFS(Flight_Data!$U$2:$U$10001,Flight_Data!$AH$2:$AH$10001,B62,Flight_Data!$R$2:$R$10001,"No") -> 131931 | D62: =IFERROR(C62/SUM(Flight_Data!$U$2:$U$10001),0) -> 0.098015995
B63: Total | C63: =SUM(C59:C62) -> 1346015 | D63: =SUM(D59:D62) -> 1

Sheet Route Analytics
B1: Route Analytics
B5: TOP ROUTE (by pax) | C5: TOP ROUTE PASSENGERS | D5: AVG DISTANCE (KM) | E5: LONGEST ROUTE (KM) | F5: SHORTEST ROUTE (KM) | G5: TOP-10 SHARE OF PAX
B6: =INDEX(E27:E36,MATCH(MAX(G27:G36),G27:G36,0)) -> Ahmedabad - Goa | C6: =MAX(G27:G36) -> 19700 | D6: =AVERAGE(Flight_Data!$I$2:$I$10001) -> 1371.7468 | E6: =MAX(Flight_Data!$I$2:$I$10001) -> 2399 | F6: =MIN(Flight_Data!$I$2:$I$10001) -> 350 | G6: =IFERROR(G37/SUM(Flight_Data!$U$2:$U$10001),0) -> 0.13082246
B25: Top 10 Routes (ranked by passengers)
B26: Rank | C26: Origin | D26: Destination | E26: Route | F26: Flights | G26: Passengers | H26: Avg Distance (KM) | I26: Revenue (₹ Cr) | J26: Load Factor
B27: 1 | C27: Ahmedabad | D27: Goa | E27: =C27&" - "&D27 -> Ahmedabad - Goa | F27: =COUNTIFS(Flight_Data!$G$2:$G$10001,C27,Flight_Data!$H$2:$H$10001,D27,Flight_Data!$R$2:$R$10001,"No") -> 139 | G27: =SUMIFS(Flight_Data!$U$2:$U$10001,Flight_Data!$G$2:$G$10001,C27,Flight_Data!$H$2:$H$10001,D27,Flight_Data!$R$2:$R$10001,"No") -> 19700 | H27: =AVERAGEIFS(Flight_Data!$I$2:$I$10001,Flight_Data!$G$2:$G$10001,C27,Flight_Data!$H$2:$H$10001,D27) -> 1408.3904 | I27: =SUMIFS(Flight_Data!$AB$2:$AB$10001,Flight_Data!$G$2:$G$10001,C27,Flight_Data!$H$2:$H$10001,D27)/10000000 -> 15.214373 | J27: =IFERROR(G27/SUMIFS(Flight_Data!$T$2:$T$10001,Flight_Data!$G$2:$G$10001,C27,Flight_Data!$H$2:$H$10001,D27,Flight_Data!$R$2:$R$10001,"No"),0) -> 0.77801035
B28: 2 | C28: Jaipur | D28: Chennai | E28: =C28&" - "&D28 -> Jaipur - Chennai | F28: =COUNTIFS(Flight_Data!$G$2:$G$10001,C28,Flight_Data!$H$2:$H$10001,D28,Flight_Data!$R$2:$R$10001,"No") -> 130 | G28: =SUMIFS(Flight_Data!$U$2:$U$10001,Flight_Data!$G$2:$G$10001,C28,Flight_Data!$H$2:$H$10001,D28,Flight_Data!$R$2:$R$10001,"No") -> 18776 | H28: =AVERAGEIFS(Flight_Data!$I$2:$I$10001,Flight_Data!$G$2:$G$10001,C28,Flight_Data!$H$2:$H$10001,D28) -> 1393.4 | I28: =SUMIFS(Flight_Data!$AB$2:$AB$10001,Flight_Data!$G$2:$G$10001,C28,Flight_Data!$H$2:$H$10001,D28)/10000000 -> 14.769963 | J28: =IFERROR(G28/SUMIFS(Flight_Data!$T$2:$T$10001,Flight_Data!$G$2:$G$10001,C28,Flight_Data!$H$2:$H$10001,D28,Flight_Data!$R$2:$R$10001,"No"),0) -> 0.78870873
B29: 3 | C29: Pune | D29: Mumbai | E29: =C29&" - "&D29 -> Pune - Mumbai | F29: =COUNTIFS(Flight_Data!$G$2:$G$10001,C29,Flight_Data!$H$2:$H$10001,D29,Flight_Data!$R$2:$R$10001,"No") -> 124 | G29: =SUMIFS(Flight_Data!$U$2:$U$10001,Flight_Data!$G$2:$G$10001,C29,Flight_Data!$H$2:$H$10001,D29,Flight_Data!$R$2:$R$10001,"No") -> 17690 | H29: =AVERAGEIFS(Flight_Data!$I$2:$I$10001,Flight_Data!$G$2:$G$10001,C29,Flight_Data!$H$2:$H$10001,D29) -> 1401.7537 | I29: =SUMIFS(Flight_Data!$AB$2:$AB$10001,Flight_Data!$G$2:$G$10001,C29,Flight_Data!$H$2:$H$10001,D29)/10000000 -> 13.409962 | J29: =IFERROR(G29/SUMIFS(Flight_Data!$T$2:$T$10001,Flight_Data!$G$2:$G$10001,C29,Flight_Data!$H$2:$H$10001,D29,Flight_Data!$R$2:$R$10001,"No"),0) -> 0.78350607
B30: 4 | C30: Pune | D30: Bengaluru | E30: =C30&" - "&D30 -> Pune - Bengaluru | F30: =COUNTIFS(Flight_Data!$G$2:$G$10001,C30,Flight_Data!$H$2:$H$10001,D30,Flight_Data!$R$2:$R$10001,"No") -> 122 | G30: =SUMIFS(Flight_Data!$U$2:$U$10001,Flight_Data!$G$2:$G$10001,C30,Flight_Data!$H$2:$H$10001,D30,Flight_Data!$R$2:$R$10001,"No") -> 17347 | H30: =AVERAGEIFS(Flight_Data!$I$2:$I$10001,Flight_Data!$G$2:$G$10001,C30,Flight_Data!$H$2:$H$10001,D30) -> 1374.3101 | I30: =SUMIFS(Flight_Data!$AB$2:$AB$10001,Flight_Data!$G$2:$G$10001,C30,Flight_Data!$H$2:$H$10001,D30)/10000000 -> 12.886634 | J30: =IFERROR(G30/SUMIFS(Flight_Data!$T$2:$T$10001,Flight_Data!$G$2:$G$10001,C30,Flight_Data!$H$2:$H$10001,D30,Flight_Data!$R$2:$R$10001,"No"),0) -> 0.76223745
B31: 5 | C31: Ahmedabad | D31: Jaipur | E31: =C31&" - "&D31 -> Ahmedabad - Jaipur | F31: =COUNTIFS(Flight_Data!$G$2:$G$10001,C31,Flight_Data!$H$2:$H$10001,D31,Flight_Data!$R$2:$R$10001,"No") -> 121 | G31: =SUMIFS(Flight_Data!$U$2:$U$10001,Flight_Data!$G$2:$G$10001,C31,Flight_Data!$H$2:$H$10001,D31,Flight_Data!$R$2:$R$10001,"No") -> 17263 | H31: =AVERAGEIFS(Flight_Data!$I$2:$I$10001,Flight_Data!$G$2:$G$10001,C31,Flight_Data!$H$2:$H$10001,D31) -> 1426.056 | I31: =SUMIFS(Flight_Data!$AB$2:$AB$10001,Flight_Data!$G$2:$G$10001,C31,Flight_Data!$H$2:$H$10001,D31)/10000000 -> 13.42818 | J31: =IFERROR(G31/SUMIFS(Flight_Data!$T$2:$T$10001,Flight_Data!$G$2:$G$10001,C31,Flight_Data!$H$2:$H$10001,D31,Flight_Data!$R$2:$R$10001,"No"),0) -> 0.77139282
B32: 6 | C32: Hyderabad | D32: Pune | E32: =C32&" - "&D32 -> Hyderabad - Pune | F32: =COUNTIFS(Flight_Data!$G$2:$G$10001,C32,Flight_Data!$H$2:$H$10001,D32,Flight_Data!$R$2:$R$10001,"No") -> 119 | G32: =SUMIFS(Flight_Data!$U$2:$U$10001,Flight_Data!$G$2:$G$10001,C32,Flight_Data!$H$2:$H$10001,D32,Flight_Data!$R$2:$R$10001,"No") -> 17153 | H32: =AVERAGEIFS(Flight_Data!$I$2:$I$10001,Flight_Data!$G$2:$G$10001,C32,Flight_Data!$H$2:$H$10001,D32) -> 1360.2778 | I32: =SUMIFS(Flight_Data!$AB$2:$AB$10001,Flight_Data!$G$2:$G$10001,C32,Flight_Data!$H$2:$H$10001,D32)/10000000 -> 12.801141 | J32: =IFERROR(G32/SUMIFS(Flight_Data!$T$2:$T$10001,Flight_Data!$G$2:$G$10001,C32,Flight_Data!$H$2:$H$10001,D32,Flight_Data!$R$2:$R$10001,"No"),0) -> 0.77384282
B33: 7 | C33: Chennai | D33: Bengaluru | E33: =C33&" - "&D33 -> Chennai - Bengaluru | F33: =COUNTIFS(Flight_Data!$G$2:$G$10001,C33,Flight_Data!$H$2:$H$10001,D33,Flight_Data!$R$2:$R$10001,"No") -> 118 | G33: =SUMIFS(Flight_Data!$U$2:$U$10001,Flight_Data!$G$2:$G$10001,C33,Flight_Data!$H$2:$H$10001,D33,Flight_Data!$R$2:$R$10001,"No") -> 17083 | H33: =AVERAGEIFS(Flight_Data!$I$2:$I$10001,Flight_Data!$G$2:$G$10001,C33,Flight_Data!$H$2:$H$10001,D33) -> 1353.7615 | I33: =SUMIFS(Flight_Data!$AB$2:$AB$10001,Flight_Data!$G$2:$G$10001,C33,Flight_Data!$H$2:$H$10001,D33)/10000000 -> 12.991003 | J33: =IFERROR(G33/SUMIFS(Flight_Data!$T$2:$T$10001,Flight_Data!$G$2:$G$10001,C33,Flight_Data!$H$2:$H$10001,D33,Flight_Data!$R$2:$R$10001,"No"),0) -> 0.78222446
B34: 8 | C34: Hyderabad | D34: Delhi | E34: =C34&" - "&D34 -> Hyderabad - Delhi | F34: =COUNTIFS(Flight_Data!$G$2:$G$10001,C34,Flight_Data!$H$2:$H$10001,D34,Flight_Data!$R$2:$R$10001,"No") -> 117 | G34: =SUMIFS(Flight_Data!$U$2:$U$10001,Flight_Data!$G$2:$G$10001,C34,Flight_Data!$H$2:$H$10001,D34,Flight_Data!$R$2:$R$10001,"No") -> 17048 | H34: =AVERAGEIFS(Flight_Data!$I$2:$I$10001,Flight_Data!$G$2:$G$10001,C34,Flight_Data!$H$2:$H$10001,D34) -> 1367.4496 | I34: =SUMIFS(Flight_Data!$AB$2:$AB$10001,Flight_Data!$G$2:$G$10001,C34,Flight_Data!$H$2:$H$10001,D34)/10000000 -> 13.527563 | J34: =IFERROR(G34/SUMIFS(Flight_Data!$T$2:$T$10001,Flight_Data!$G$2:$G$10001,C34,Flight_Data!$H$2:$H$10001,D34,Flight_Data!$R$2:$R$10001,"No"),0) -> 0.78812815
B35: 9 | C35: Ahmedabad | D35: Bengaluru | E35: =C35&" - "&D35 -> Ahmedabad - Bengaluru | F35: =COUNTIFS(Flight_Data!$G$2:$G$10001,C35,Flight_Data!$H$2:$H$10001,D35,Flight_Data!$R$2:$R$10001,"No") -> 116 | G35: =SUMIFS(Flight_Data!$U$2:$U$10001,Flight_Data!$G$2:$G$10001,C35,Flight_Data!$H$2:$H$10001,D35,Flight_Data!$R$2:$R$10001,"No") -> 17044 | H35: =AVERAGEIFS(Flight_Data!$I$2:$I$10001,Flight_Data!$G$2:$G$10001,C35,Flight_Data!$H$2:$H$10001,D35) -> 1360.7851 | I35: =SUMIFS(Flight_Data!$AB$2:$AB$10001,Flight_Data!$G$2:$G$10001,C35,Flight_Data!$H$2:$H$10001,D35)/10000000 -> 13.660535 | J35: =IFERROR(G35/SUMIFS(Flight_Data!$T$2:$T$10001,Flight_Data!$G$2:$G$10001,C35,Flight_Data!$H$2:$H$10001,D35,Flight_Data!$R$2:$R$10001,"No"),0) -> 0.79123532
B36: 10 | C36: Goa | D36: Bengaluru | E36: =C36&" - "&D36 -> Goa - Bengaluru | F36: =COUNTIFS(Flight_Data!$G$2:$G$10001,C36,Flight_Data!$H$2:$H$10001,D36,Flight_Data!$R$2:$R$10001,"No") -> 121 | G36: =SUMIFS(Flight_Data!$U$2:$U$10001,Flight_Data!$G$2:$G$10001,C36,Flight_Data!$H$2:$H$10001,D36,Flight_Data!$R$2:$R$10001,"No") -> 16985 | H36: =AVERAGEIFS(Flight_Data!$I$2:$I$10001,Flight_Data!$G$2:$G$10001,C36,Flight_Data!$H$2:$H$10001,D36) -> 1303.7619 | I36: =SUMIFS(Flight_Data!$AB$2:$AB$10001,Flight_Data!$G$2:$G$10001,C36,Flight_Data!$H$2:$H$10001,D36)/10000000 -> 13.047887 | J36: =IFERROR(G36/SUMIFS(Flight_Data!$T$2:$T$10001,Flight_Data!$G$2:$G$10001,C36,Flight_Data!$H$2:$H$10001,D36,Flight_Data!$R$2:$R$10001,"No"),0) -> 0.75485534
B37: Total | F37: =SUM(F27:F36) -> 1227 | G37: =SUM(G27:G36) -> 176089 | I37: =SUM(I27:I36) -> 135.73724
B40: Route Heatmap – Operated Flights (Origin vs Destination)
B41: Origin \ Dest | C41: Ahmedabad | D41: Bengaluru | E41: Chennai | F41: Delhi | G41: Goa | H41: Hyderabad | I41: Jaipur | J41: Kolkata | K41: Mumbai | L41: Pune
B42: Ahmedabad | C42: =COUNTIFS(Flight_Data!$G$2:$G$10001,$B42,Flight_Data!$H$2:$H$10001,C$41,Flight_Data!$R$2:$R$10001,"No") -> 0 | D42: =COUNTIFS(Flight_Data!$G$2:$G$10001,$B42,Flight_Data!$H$2:$H$10001,D$41,Flight_Data!$R$2:$R$10001,"No") -> 116 | E42: =COUNTIFS(Flight_Data!$G$2:$G$10001,$B42,Flight_Data!$H$2:$H$10001,E$41,Flight_Data!$R$2:$R$10001,"No") -> 99 | F42: =COUNTIFS(Flight_Data!$G$2:$G$10001,$B42,Flight_Data!$H$2:$H$10001,F$41,Flight_Data!$R$2:$R$10001,"No") -> 94 | G42: =COUNTIFS(Flight_Data!$G$2:$G$10001,$B42,Flight_Data!$H$2:$H$10001,G$41,Flight_Data!$R$2:$R$10001,"No") -> 139 | H42: =COUNTIFS(Flight_Data!$G$2:$G$10001,$B42,Flight_Data!$H$2:$H$10001,H$41,Flight_Data!$R$2:$R$10001,"No") -> 90 | I42: =COUNTIFS(Flight_Data!$G$2:$G$10001,$B42,Flight_Data!$H$2:$H$10001,I$41,Flight_Data!$R$2:$R$10001,"No") -> 121 | J42: =COUNTIFS(Flight_Data!$G$2:$G$10001,$B42,Flight_Data!$H$2:$H$10001,J$41,Flight_Data!$R$2:$R$10001,"No") -> 115 | ... L42: =COUNTIFS(Flight_Data!$G$2:$G$10001,$B42,Flight_Data!$H$2:$H$10001,L$41,Flight_Data!$R$2:$R$10001,"No") -> 90
B43: Bengaluru | C43: =COUNTIFS(Flight_Data!$G$2:$G$10001,$B43,Flight_Data!$H$2:$H$10001,C$41,Flight_Data!$R$2:$R$10001,"No") -> 94 | D43: =COUNTIFS(Flight_Data!$G$2:$G$10001,$B43,Flight_Data!$H$2:$H$10001,D$41,Flight_Data!$R$2:$R$10001,"No") -> 0 | E43: =COUNTIFS(Flight_Data!$G$2:$G$10001,$B43,Flight_Data!$H$2:$H$10001,E$41,Flight_Data!$R$2:$R$10001,"No") -> 116 | F43: =COUNTIFS(Flight_Data!$G$2:$G$10001,$B43,Flight_Data!$H$2:$H$10001,F$41,Flight_Data!$R$2:$R$10001,"No") -> 117 | G43: =COUNTIFS(Flight_Data!$G$2:$G$10001,$B43,Flight_Data!$H$2:$H$10001,G$41,Flight_Data!$R$2:$R$10001,"No") -> 100 | H43: =COUNTIFS(Flight_Data!$G$2:$G$10001,$B43,Flight_Data!$H$2:$H$10001,H$41,Flight_Data!$R$2:$R$10001,"No") -> 103 | I43: =COUNTIFS(Flight_Data!$G$2:$G$10001,$B43,Flight_Data!$H$2:$H$10001,I$41,Flight_Data!$R$2:$R$10001,"No") -> 113 | J43: =COUNTIFS(Flight_Data!$G$2:$G$10001,$B43,Flight_Data!$H$2:$H$10001,J$41,Flight_Data!$R$2:$R$10001,"No") -> 98 | ... L43: =COUNTIFS(Flight_Data!$G$2:$G$10001,$B43,Flight_Data!$H$2:$H$10001,L$41,Flight_Data!$R$2:$R$10001,"No") -> 91
B44: Chennai | C44: =COUNTIFS(Flight_Data!$G$2:$G$10001,$B44,Flight_Data!$H$2:$H$10001,C$41,Flight_Data!$R$2:$R$10001,"No") -> 93 | D44: =COUNTIFS(Flight_Data!$G$2:$G$10001,$B44,Flight_Data!$H$2:$H$10001,D$41,Flight_Data!$R$2:$R$10001,"No") -> 118 | E44: =COUNTIFS(Flight_Data!$G$2:$G$10001,$B44,Flight_Data!$H$2:$H$10001,E$41,Flight_Data!$R$2:$R$10001,"No") -> 0 | F44: =COUNTIFS(Flight_Data!$G$2:$G$10001,$B44,Flight_Data!$H$2:$H$10001,F$41,Flight_Data!$R$2:$R$10001,"No") -> 102 | G44: =COUNTIFS(Flight_Data!$G$2:$G$10001,$B44,Flight_Data!$H$2:$H$10001,G$41,Flight_Data!$R$2:$R$10001,"No") -> 96 | H44: =COUNTIFS(Flight_Data!$G$2:$G$10001,$B44,Flight_Data!$H$2:$H$10001,H$41,Flight_Data!$R$2:$R$10001,"No") -> 113 | I44: =COUNTIFS(Flight_Data!$G$2:$G$10001,$B44,Flight_Data!$H$2:$H$10001,I$41,Flight_Data!$R$2:$R$10001,"No") -> 94 | J44: =COUNTIFS(Flight_Data!$G$2:$G$10001,$B44,Flight_Data!$H$2:$H$10001,J$41,Flight_Data!$R$2:$R$10001,"No") -> 108 | ... L44: =COUNTIFS(Flight_Data!$G$2:$G$10001,$B44,Flight_Data!$H$2:$H$10001,L$41,Flight_Data!$R$2:$R$10001,"No") -> 83
B45: Delhi | C45: =COUNTIFS(Flight_Data!$G$2:$G$10001,$B45,Flight_Data!$H$2:$H$10001,C$41,Flight_Data!$R$2:$R$10001,"No") -> 89 | D45: =COUNTIFS(Flight_Data!$G$2:$G$10001,$B45,Flight_Data!$H$2:$H$10001,D$41,Flight_Data!$R$2:$R$10001,"No") -> 103 | E45: =COUNTIFS(Flight_Data!$G$2:$G$10001,$B45,Flight_Data!$H$2:$H$10001,E$41,Flight_Data!$R$2:$R$10001,"No") -> 110 | F45: =COUNTIFS(Flight_Data!$G$2:$G$10001,$B45,Flight_Data!$H$2:$H$10001,F$41,Flight_Data!$R$2:$R$10001,"No") -> 0 | G45: =COUNTIFS(Flight_Data!$G$2:$G$10001,$B45,Flight_Data!$H$2:$H$10001,G$41,Flight_Data!$R$2:$R$10001,"No") -> 118 | H45: =COUNTIFS(Flight_Data!$G$2:$G$10001,$B45,Flight_Data!$H$2:$H$10001,H$41,Flight_Data!$R$2:$R$10001,"No") -> 113 | I45: =COUNTIFS(Flight_Data!$G$2:$G$10001,$B45,Flight_Data!$H$2:$H$10001,I$41,Flight_Data!$R$2:$R$10001,"No") -> 101 | J45: =COUNTIFS(Flight_Data!$G$2:$G$10001,$B45,Flight_Data!$H$2:$H$10001,J$41,Flight_Data!$R$2:$R$10001,"No") -> 104 | ... L45: =COUNTIFS(Flight_Data!$G$2:$G$10001,$B45,Flight_Data!$H$2:$H$10001,L$41,Flight_Data!$R$2:$R$10001,"No") -> 103
B46: Goa | C46: =COUNTIFS(Flight_Data!$G$2:$G$10001,$B46,Flight_Data!$H$2:$H$10001,C$41,Flight_Data!$R$2:$R$10001,"No") -> 104 | D46: =COUNTIFS(Flight_Data!$G$2:$G$10001,$B46,Flight_Data!$H$2:$H$10001,D$41,Flight_Data!$R$2:$R$10001,"No") -> 121 | E46: =COUNTIFS(Flight_Data!$G$2:$G$10001,$B46,Flight_Data!$H$2:$H$10001,E$41,Flight_Data!$R$2:$R$10001,"No") -> 101 | F46: =COUNTIFS(Flight_Data!$G$2:$G$10001,$B46,Flight_Data!$H$2:$H$10001,F$41,Flight_Data!$R$2:$R$10001,"No") -> 103 | G46: =COUNTIFS(Flight_Data!$G$2:$G$10001,$B46,Flight_Data!$H$2:$H$10001,G$41,Flight_Data!$R$2:$R$10001,"No") -> 0 | H46: =COUNTIFS(Flight_Data!$G$2:$G$10001,$B46,Flight_Data!$H$2:$H$10001,H$41,Flight_Data!$R$2:$R$10001,"No") -> 100 | I46: =COUNTIFS(Flight_Data!$G$2:$G$10001,$B46,Flight_Data!$H$2:$H$10001,I$41,Flight_Data!$R$2:$R$10001,"No") -> 84 | J46: =COUNTIFS(Flight_Data!$G$2:$G$10001,$B46,Flight_Data!$H$2:$H$10001,J$41,Flight_Data!$R$2:$R$10001,"No") -> 103 | ... L46: =COUNTIFS(Flight_Data!$G$2:$G$10001,$B46,Flight_Data!$H$2:$H$10001,L$41,Flight_Data!$R$2:$R$10001,"No") -> 107
B47: Hyderabad | C47: =COUNTIFS(Flight_Data!$G$2:$G$10001,$B47,Flight_Data!$H$2:$H$10001,C$41,Flight_Data!$R$2:$R$10001,"No") -> 103 | D47: =COUNTIFS(Flight_Data!$G$2:$G$10001,$B47,Flight_Data!$H$2:$H$10001,D$41,Flight_Data!$R$2:$R$10001,"No") -> 98 | E47: =COUNTIFS(Flight_Data!$G$2:$G$10001,$B47,Flight_Data!$H$2:$H$10001,E$41,Flight_Data!$R$2:$R$10001,"No") -> 95 | F47: =COUNTIFS(Flight_Data!$G$2:$G$10001,$B47,Flight_Data!$H$2:$H$10001,F$41,Flight_Data!$R$2:$R$10001,"No") -> 117 | G47: =COUNTIFS(Flight_Data!$G$2:$G$10001,$B47,Flight_Data!$H$2:$H$10001,G$41,Flight_Data!$R$2:$R$10001,"No") -> 85 | H47: =COUNTIFS(Flight_Data!$G$2:$G$10001,$B47,Flight_Data!$H$2:$H$10001,H$41,Flight_Data!$R$2:$R$10001,"No") -> 0 | I47: =COUNTIFS(Flight_Data!$G$2:$G$10001,$B47,Flight_Data!$H$2:$H$10001,I$41,Flight_Data!$R$2:$R$10001,"No") -> 108 | J47: =COUNTIFS(Flight_Data!$G$2:$G$10001,$B47,Flight_Data!$H$2:$H$10001,J$41,Flight_Data!$R$2:$R$10001,"No") -> 109 | ... L47: =COUNTIFS(Flight_Data!$G$2:$G$10001,$B47,Flight_Data!$H$2:$H$10001,L$41,Flight_Data!$R$2:$R$10001,"No") -> 119
B48: Jaipur | C48: =COUNTIFS(Flight_Data!$G$2:$G$10001,$B48,Flight_Data!$H$2:$H$10001,C$41,Flight_Data!$R$2:$R$10001,"No") -> 90 | D48: =COUNTIFS(Flight_Data!$G$2:$G$10001,$B48,Flight_Data!$H$2:$H$10001,D$41,Flight_Data!$R$2:$R$10001,"No") -> 114 | E48: =COUNTIFS(Flight_Data!$G$2:$G$10001,$B48,Flight_Data!$H$2:$H$10001,E$41,Flight_Data!$R$2:$R$10001,"No") -> 130 | F48: =COUNTIFS(Flight_Data!$G$2:$G$10001,$B48,Flight_Data!$H$2:$H$10001,F$41,Flight_Data!$R$2:$R$10001,"No") -> 111 | G48: =COUNTIFS(Flight_Data!$G$2:$G$10001,$B48,Flight_Data!$H$2:$H$10001,G$41,Flight_Data!$R$2:$R$10001,"No") -> 112 | H48: =COUNTIFS(Flight_Data!$G$2:$G$10001,$B48,Flight_Data!$H$2:$H$10001,H$41,Flight_Data!$R$2:$R$10001,"No") -> 114 | I48: =COUNTIFS(Flight_Data!$G$2:$G$10001,$B48,Flight_Data!$H$2:$H$10001,I$41,Flight_Data!$R$2:$R$10001,"No") -> 0 | J48: =COUNTIFS(Flight_Data!$G$2:$G$10001,$B48,Flight_Data!$H$2:$H$10001,J$41,Flight_Data!$R$2:$R$10001,"No") -> 111 | ... L48: =COUNTIFS(Flight_Data!$G$2:$G$10001,$B48,Flight_Data!$H$2:$H$10001,L$41,Flight_Data!$R$2:$R$10001,"No") -> 104
B49: Kolkata | C49: =COUNTIFS(Flight_Data!$G$2:$G$10001,$B49,Flight_Data!$H$2:$H$10001,C$41,Flight_Data!$R$2:$R$10001,"No") -> 97 | D49: =COUNTIFS(Flight_Data!$G$2:$G$10001,$B49,Flight_Data!$H$2:$H$10001,D$41,Flight_Data!$R$2:$R$10001,"No") -> 99 | E49: =COUNTIFS(Flight_Data!$G$2:$G$10001,$B49,Flight_Data!$H$2:$H$10001,E$41,Flight_Data!$R$2:$R$10001,"No") -> 97 | F49: =COUNTIFS(Flight_Data!$G$2:$G$10001,$B49,Flight_Data!$H$2:$H$10001,F$41,Flight_Data!$R$2:$R$10001,"No") -> 105 | G49: =COUNTIFS(Flight_Data!$G$2:$G$10001,$B49,Flight_Data!$H$2:$H$10001,G$41,Flight_Data!$R$2:$R$10001,"No") -> 112 | H49: =COUNTIFS(Flight_Data!$G$2:$G$10001,$B49,Flight_Data!$H$2:$H$10001,H$41,Flight_Data!$R$2:$R$10001,"No") -> 95 | I49: =COUNTIFS(Flight_Data!$G$2:$G$10001,$B49,Flight_Data!$H$2:$H$10001,I$41,Flight_Data!$R$2:$R$10001,"No") -> 87 | J49: =COUNTIFS(Flight_Data!$G$2:$G$10001,$B49,Flight_Data!$H$2:$H$10001,J$41,Flight_Data!$R$2:$R$10001,"No") -> 0 | ... L49: =COUNTIFS(Flight_Data!$G$2:$G$10001,$B49,Flight_Data!$H$2:$H$10001,L$41,Flight_Data!$R$2:$R$10001,"No") -> 103
B50: Mumbai | C50: =COUNTIFS(Flight_Data!$G$2:$G$10001,$B50,Flight_Data!$H$2:$H$10001,C$41,Flight_Data!$R$2:$R$10001,"No") -> 106 | D50: =COUNTIFS(Flight_Data!$G$2:$G$10001,$B50,Flight_Data!$H$2:$H$10001,D$41,Flight_Data!$R$2:$R$10001,"No") -> 117 | E50: =COUNTIFS(Flight_Data!$G$2:$G$10001,$B50,Flight_Data!$H$2:$H$10001,E$41,Flight_Data!$R$2:$R$10001,"No") -> 94 | F50: =COUNTIFS(Flight_Data!$G$2:$G$10001,$B50,Flight_Data!$H$2:$H$10001,F$41,Flight_Data!$R$2:$R$10001,"No") -> 106 | G50: =COUNTIFS(Flight_Data!$G$2:$G$10001,$B50,Flight_Data!$H$2:$H$10001,G$41,Flight_Data!$R$2:$R$10001,"No") -> 94 | H50: =COUNTIFS(Flight_Data!$G$2:$G$10001,$B50,Flight_Data!$H$2:$H$10001,H$41,Flight_Data!$R$2:$R$10001,"No") -> 120 | I50: =COUNTIFS(Flight_Data!$G$2:$G$10001,$B50,Flight_Data!$H$2:$H$10001,I$41,Flight_Data!$R$2:$R$10001,"No") -> 100 | J50: =COUNTIFS(Flight_Data!$G$2:$G$10001,$B50,Flight_Data!$H$2:$H$10001,J$41,Flight_Data!$R$2:$R$10001,"No") -> 96 | ... L50: =COUNTIFS(Flight_Data!$G$2:$G$10001,$B50,Flight_Data!$H$2:$H$10001,L$41,Flight_Data!$R$2:$R$10001,"No") -> 115
B51: Pune | C51: =COUNTIFS(Flight_Data!$G$2:$G$10001,$B51,Flight_Data!$H$2:$H$10001,C$41,Flight_Data!$R$2:$R$10001,"No") -> 105 | D51: =COUNTIFS(Flight_Data!$G$2:$G$10001,$B51,Flight_Data!$H$2:$H$10001,D$41,Flight_Data!$R$2:$R$10001,"No") -> 122 | E51: =COUNTIFS(Flight_Data!$G$2:$G$10001,$B51,Flight_Data!$H$2:$H$10001,E$41,Flight_Data!$R$2:$R$10001,"No") -> 110 | F51: =COUNTIFS(Flight_Data!$G$2:$G$10001,$B51,Flight_Data!$H$2:$H$10001,F$41,Flight_Data!$R$2:$R$10001,"No") -> 86 | G51: =COUNTIFS(Flight_Data!$G$2:$G$10001,$B51,Flight_Data!$H$2:$H$10001,G$41,Flight_Data!$R$2:$R$10001,"No") -> 106 | H51: =COUNTIFS(Flight_Data!$G$2:$G$10001,$B51,Flight_Data!$H$2:$H$10001,H$41,Flight_Data!$R$2:$R$10001,"No") -> 117 | I51: =COUNTIFS(Flight_Data!$G$2:$G$10001,$B51,Flight_Data!$H$2:$H$10001,I$41,Flight_Data!$R$2:$R$10001,"No") -> 106 | J51: =COUNTIFS(Flight_Data!$G$2:$G$10001,$B51,Flight_Data!$H$2:$H$10001,J$41,Flight_Data!$R$2:$R$10001,"No") -> 114 | ... L51: =COUNTIFS(Flight_Data!$G$2:$G$10001,$B51,Flight_Data!$H$2:$H$10001,L$41,Flight_Data!$R$2:$R$10001,"No") -> 0

Sheet Airport Performance
B1: Airport Performance
B5: AIRPORTS | C5: TOTAL DEPARTURES | D5: BUSIEST AIRPORT | E5: HIGHEST DELAY RATE | F5: HIGHEST CANCEL RATE | G5: BEST ON-TIME AIRPORT
B6: =COUNTA(B43:B52) -> 10 | C6: =COUNTA(Flight_Data!$A$2:$A$10001) -> 10000 | D6: =INDEX(B43:B52,MATCH(MAX(C43:C52),C43:C52,0)) -> Pune (PNQ) | E6: =INDEX(B43:B52,MATCH(MAX(F43:F52),F43:F52,0)) -> Kolkata (CCU) | F6: =INDEX(B43:B52,MATCH(MAX(H43:H52),H43:H52,0)) -> Delhi (DEL) | G6: =INDEX(B43:B52,MATCH(MIN(F43:F52),F43:F52,0)) -> Pune (PNQ)
B41: Airport Summary
B42: Airport | C42: Departures | D42: Arrivals | E42: Delayed | F42: Delay Rate | G42: Cancelled | H42: Cancel Rate | I42: Avg Dep Delay (min) | J42: Passengers
B43: Ahmedabad (AMD) | C43: =COUNTIF(Flight_Data!$E$2:$E$10001,B43) -> 1026 | D43: =COUNTIF(Flight_Data!$F$2:$F$10001,B43) -> 940 | E43: =COUNTIFS(Flight_Data!$E$2:$E$10001,B43,Flight_Data!$Q$2:$Q$10001,"Delayed*") -> 787 | F43: =IFERROR(E43/(C43-G43),0) -> 0.80967078 | G43: =COUNTIFS(Flight_Data!$E$2:$E$10001,B43,Flight_Data!$R$2:$R$10001,"Yes") -> 54 | H43: =IFERROR(G43/C43,0) -> 0.052631579 | I43: =AVERAGEIFS(Flight_Data!$O$2:$O$10001,Flight_Data!$E$2:$E$10001,B43,Flight_Data!$R$2:$R$10001,"No") -> 17.12963 | J43: =SUMIF(Flight_Data!$E$2:$E$10001,B43,Flight_Data!$U$2:$U$10001) -> 140231
B44: Bengaluru (BLR) | C44: =COUNTIF(Flight_Data!$E$2:$E$10001,B44) -> 985 | D44: =COUNTIF(Flight_Data!$F$2:$F$10001,B44) -> 1076 | E44: =COUNTIFS(Flight_Data!$E$2:$E$10001,B44,Flight_Data!$Q$2:$Q$10001,"Delayed*") -> 747 | F44: =IFERROR(E44/(C44-G44),0) -> 0.80409042 | G44: =COUNTIFS(Flight_Data!$E$2:$E$10001,B44,Flight_Data!$R$2:$R$10001,"Yes") -> 56 | H44: =IFERROR(G44/C44,0) -> 0.056852792 | I44: =AVERAGEIFS(Flight_Data!$O$2:$O$10001,Flight_Data!$E$2:$E$10001,B44,Flight_Data!$R$2:$R$10001,"No") -> 17.618945 | J44: =SUMIF(Flight_Data!$E$2:$E$10001,B44,Flight_Data!$U$2:$U$10001) -> 132484
B45: Chennai (MAA) | C45: =COUNTIF(Flight_Data!$E$2:$E$10001,B45) -> 971 | D45: =COUNTIF(Flight_Data!$F$2:$F$10001,B45) -> 1013 | E45: =COUNTIFS(Flight_Data!$E$2:$E$10001,B45,Flight_Data!$Q$2:$Q$10001,"Delayed*") -> 747 | F45: =IFERROR(E45/(C45-G45),0) -> 0.81997805 | G45: =COUNTIFS(Flight_Data!$E$2:$E$10001,B45,Flight_Data!$R$2:$R$10001,"Yes") -> 60 | H45: =IFERROR(G45/C45,0) -> 0.061791967 | I45: =AVERAGEIFS(Flight_Data!$O$2:$O$10001,Flight_Data!$E$2:$E$10001,B45,Flight_Data!$R$2:$R$10001,"No") -> 17.498353 | J45: =SUMIF(Flight_Data!$E$2:$E$10001,B45,Flight_Data!$U$2:$U$10001) -> 130643
B46: Delhi (DEL) | C46: =COUNTIF(Flight_Data!$E$2:$E$10001,B46) -> 1001 | D46: =COUNTIF(Flight_Data!$F$2:$F$10001,B46) -> 1004 | E46: =COUNTIFS(Flight_Data!$E$2:$E$10001,B46,Flight_Data!$Q$2:$Q$10001,"Delayed*") -> 749 | F46: =IFERROR(E46/(C46-G46),0) -> 0.80885529 | G46: =COUNTIFS(Flight_Data!$E$2:$E$10001,B46,Flight_Data!$R$2:$R$10001,"Yes") -> 75 | H46: =IFERROR(G46/C46,0) -> 0.074925075 | I46: =AVERAGEIFS(Flight_Data!$O$2:$O$10001,Flight_Data!$E$2:$E$10001,B46,Flight_Data!$R$2:$R$10001,"No") -> 16.448164 | J46: =SUMIF(Flight_Data!$E$2:$E$10001,B46,Flight_Data!$U$2:$U$10001) -> 133492
B47: Goa (GOI) | C47: =COUNTIF(Flight_Data!$E$2:$E$10001,B47) -> 985 | D47: =COUNTIF(Flight_Data!$F$2:$F$10001,B47) -> 1018 | E47: =COUNTIFS(Flight_Data!$E$2:$E$10001,B47,Flight_Data!$Q$2:$Q$10001,"Delayed*") -> 739 | F47: =IFERROR(E47/(C47-G47),0) -> 0.79805616 | G47: =COUNTIFS(Flight_Data!$E$2:$E$10001,B47,Flight_Data!$R$2:$R$10001,"Yes") -> 59 | H47: =IFERROR(G47/C47,0) -> 0.059898477 | I47: =AVERAGEIFS(Flight_Data!$O$2:$O$10001,Flight_Data!$E$2:$E$10001,B47,Flight_Data!$R$2:$R$10001,"No") -> 16.408207 | J47: =SUMIF(Flight_Data!$E$2:$E$10001,B47,Flight_Data!$U$2:$U$10001) -> 131467
B48: Hyderabad (HYD) | C48: =COUNTIF(Flight_Data!$E$2:$E$10001,B48) -> 999 | D48: =COUNTIF(Flight_Data!$F$2:$F$10001,B48) -> 1021 | E48: =COUNTIFS(Flight_Data!$E$2:$E$10001,B48,Flight_Data!$Q$2:$Q$10001,"Delayed*") -> 741 | F48: =IFERROR(E48/(C48-G48),0) -> 0.79849138 | G48: =COUNTIFS(Flight_Data!$E$2:$E$10001,B48,Flight_Data!$R$2:$R$10001,"Yes") -> 71 | H48: =IFERROR(G48/C48,0) -> 0.071071071 | I48: =AVERAGEIFS(Flight_Data!$O$2:$O$10001,Flight_Data!$E$2:$E$10001,B48,Flight_Data!$R$2:$R$10001,"No") -> 17.241379 | J48: =SUMIF(Flight_Data!$E$2:$E$10001,B48,Flight_Data!$U$2:$U$10001) -> 134451
B49: Jaipur (JAI) | C49: =COUNTIF(Flight_Data!$E$2:$E$10001,B49) -> 1023 | D49: =COUNTIF(Flight_Data!$F$2:$F$10001,B49) -> 973 | E49: =COUNTIFS(Flight_Data!$E$2:$E$10001,B49,Flight_Data!$Q$2:$Q$10001,"Delayed*") -> 788 | F49: =IFERROR(E49/(C49-G49),0) -> 0.81069959 | G49: =COUNTIFS(Flight_Data!$E$2:$E$10001,B49,Flight_Data!$R$2:$R$10001,"Yes") -> 51 | H49: =IFERROR(G49/C49,0) -> 0.049853372 | I49: =AVERAGEIFS(Flight_Data!$O$2:$O$10001,Flight_Data!$E$2:$E$10001,B49,Flight_Data!$R$2:$R$10001,"No") -> 17.083333 | J49: =SUMIF(Flight_Data!$E$2:$E$10001,B49,Flight_Data!$U$2:$U$10001) -> 139756
B50: Kolkata (CCU) | C50: =COUNTIF(Flight_Data!$E$2:$E$10001,B50) -> 938 | D50: =COUNTIF(Flight_Data!$F$2:$F$10001,B50) -> 1018 | E50: =COUNTIFS(Flight_Data!$E$2:$E$10001,B50,Flight_Data!$Q$2:$Q$10001,"Delayed*") -> 725 | F50: =IFERROR(E50/(C50-G50),0) -> 0.82199546 | G50: =COUNTIFS(Flight_Data!$E$2:$E$10001,B50,Flight_Data!$R$2:$R$10001,"Yes") -> 56 | H50: =IFERROR(G50/C50,0) -> 0.059701493 | I50: =AVERAGEIFS(Flight_Data!$O$2:$O$10001,Flight_Data!$E$2:$E$10001,B50,Flight_Data!$R$2:$R$10001,"No") -> 16.165533 | J50: =SUMIF(Flight_Data!$E$2:$E$10001,B50,Flight_Data!$U$2:$U$10001) -> 126447
